Workbook

Sheet Governor
A1: Please be advised that much of this data is incomplete due to the NYS Governor's office not having provided clear data. | C1: Total Received | D1: Total Granted | E1: Commutations Granted | F1: Pardons Granted
A2: Years in Office | B2: Governor | C2: =Summary!J2 -> 1920 | D2: =Summary!J3 -> 331 | E2: =Summary!E5 -> 74 | F2: =Summary!G5 -> 257
A3: 2021-Present | B3: Kathy Hochul (D) | C3: 1595 | D3: 43 | E3: 10 | F3: 33
A4: 2012-2021 | B4: Andrew Cuomo (D) | C4: 1585 | D4: 183 | E4: 16 | F4: 167
A5: 2008-2010 | B5: David Patterson (D) | C5: 2220 | D5: 41 | E5: 5 | F5: 36
A6: 2007 | B6: Eliot Spitzer (D) | C6: No Data | D6: No Data | E6: No Data | F6: 1
A7: 1995-2006 | B7: George Pataki (R) | C7: No Data | D7: 39 | E7: 9 | F7: 30
A8: 1985-1994 | B8: Mario Cuomo (D) | C8: No Data | D8: No Data | E8: No Data | F8: No Data
A9: 1975-1984 | B9: Hugh Leo Carey (D) | C9: No Data | D9: 20 | E9: 9 | F9: 11
A10: 1973-1974 | B10: Malcolm Wilson (R) | C10: No Data | D10: No Data | E10: No Data | F10: No Data
A11: 1959-1972 | B11: Nelson Rockefeller (R) | C11: No Data | D11: No Data | E11: No Data | F11: No Data
A12: 1955-1958 | B12: William Harriman (D) | C12: No Data | D12: No Data | E12: No Data | F12: No Data

Sheet Summary
A1: Updated: 03/21/2024
A2: Date | B2: Governor | C2: Yearly Applications Received | D2: Commutations | F2: Pardons | H2: Undetermined Grant | I2: Total Applications Received: | J2: =E4+G4 -> 1920
I3: Total Applications Granted: | J3: =SUM(I7:I1008) -> 331
C4: Total | D4: Received: | E4: =SUM(D7:D1008) -> 1277 | F4: Received: | G4: =SUM(F7:F1008) -> 643 | H4: Total
C5: =SUM(C7:C97) -> 2045 | D5: Granted: | E5: =SUM(E7:E97) -> 74 | F5: Granted: | G5: =SUM(G7:G1008) -> 257 | H5: =SUM(H7:H97) -> 0
D6: Received | E6: Granted | F6: Received | G6: Granted | I6: Yearly Grant Totals | J6: Sources
A7: 2023 | B7: Kathy Hochul (D) | C7: 1595 | D7: 1139 | E7: 9 | F7: 456 | G7: 27 | I7: =SUM(E7,G7,H7) -> 36
A8: 2022 | B8: Kathy Hochul (D) | C8: No data | D8: No data | E8: 4 | F8: No data | G8: 9 | I8: =SUM(E8,G8,H8) -> 13
A9: 2021 | B9: Kathy Hochul (D) | C9: No data | D9: No data | E9: 1 | F9: No data | G9: 9 | I9: =SUM(E9,G9,H9) -> 10
A10: 2021 | B10: Andrew Cuomo (D) | C10: No data | D10: No data | E10: 4 | F10: No data | G10: 6 | I10: =SUM(E10,G10,H10) -> 10
A11: 2020 | B11: Andrew Cuomo (D) | C11: No data | D11: No data | E11: 7 | F11: No data | G11: 14 | I11: =SUM(E11,G11,H11) -> 21 | J11: 14
A12: 2019 | B12: Andrew Cuomo (D) | C12: No data | D12: No data | E12: No data | F12: No data | G12: No data | I12: =SUM(E12,G12,H12) -> 0
A13: 2018 | B13: Andrew Cuomo (D) | C13: No data | D13: No data | E13: No data | F13: No data | G13: No data | I13: =SUM(E13,G13,H13) -> 0
A14: 2017 | B14: Andrew Cuomo (D) | C14: No data | D14: No data | E14: 2 | F14: No data | G14: 57 | I14: =SUM(E14,G14,H14) -> 59 | J14: 18 | K14: 19
A15: 2016 | B15: Andrew Cuomo (D) | C15: No data | D15: No data | E15: 7 | F15: No data | G15: 106 | I15: =SUM(E15,G15,H15) -> 113 | J15: 17
A16: 2015 | B16: Andrew Cuomo (D) | C16: No data | D16: No data | E16: 2 | F16: No data | G16: 2 | I16: =SUM(E16,G16,H16) -> 4 | J16: 20
A17: 2014 | B17: Andrew Cuomo (D) | C17: No data | D17: No data | E17: 0 | F17: No data | G17: 2 | I17: =SUM(E17,G17,H17) -> 2
A18: 2013 | B18: Andrew Cuomo (D) | C18: No data | D18: No data | E18: 0 | F18: No data | G18: 3 | I18: =SUM(E18,G18,H18) -> 3 | J18: 13
A19: 2012 | B19: Andrew Cuomo (D) | C19: No data | D19: No data | E19: 0 | F19: No data | G19: 3 | I19: =SUM(E19,G19,H19) -> 3
A20: 2011 | B20: Andrew Cuomo (D) | C20: No data | D20: No data | E20: 0 | F20: No data | G20: 0 | I20: =SUM(E20,G20,H20) -> 0
A21: 2010 | B21: David Patterson (D) | C21: No data | D21: No data | E21: 1 | F21: No data | G21: 0 | I21: =SUM(E21,G21,H21) -> 1 | J21: 11 | K21: 12
A22: 2009 | B22: David Patterson (D) | C22: No data | D22: No data | E22: 1 | F22: No data | G22: 1 | I22: =SUM(E22,G22,H22) -> 2
A23: 2008 | B23: David Patterson (D) | C23: 450 | D23: No data | E23: 2 | F23: No data | G23: 0 | I23: =SUM(E23,G23,H23) -> 2 | J23: 10
A24: 2007 | B24: Eliot Spitzer (D) | C24: No data | D24: No data | E24: 0 | F24: No data | G24: 1 | I24: =SUM(E24,G24,H24) -> 1 | J24: 9
A25: 2006 | B25: George Pataki (R) | C25: No data | D25: 138 | E25: 0 | F25: 187 | G25: 0 | I25: =SUM(E25,G25,H25) -> 0
A26: 2005 | B26: George Pataki (R) | C26: No data | D26: No data | E26: 1 | F26: No data | G26: 0 | I26: =SUM(E26,G26,H26) -> 1 | J26: 8
A27: 2004 | B27: George Pataki (R) | C27: No data | D27: No data | E27: 0 | F27: No data | G27: 0 | I27: =SUM(E27,G27,H27) -> 0
A28: 2003 | B28: George Pataki (R) | C28: No data | D28: No data | E28: 0 | F28: No data | G28: 3 | I28: =SUM(E28,G28,H28) -> 3
A29: 2002 | B29: George Pataki (R) | C29: No data | D29: No data | E29: 4 | F29: No data | G29: 0 | I29: =SUM(E29,G29,H29) -> 4 | J29: 7 | K29: 15
A30: 2001 | B30: George Pataki (R) | C30: No data | D30: No data | E30: 2 | F30: No data | G30: 0 | I30: =SUM(E30,G30,H30) -> 2 | J30: 16
A31: 2000 | B31: George Pataki (R) | C31: No data | D31: No data | E31: 0 | F31: No data | G31: 5 | I31: =SUM(E31,G31,H31) -> 5
A32: 1999 | B32: George Pataki (R) | C32: No data | D32: No data | E32: 4 | F32: No data | G32: 0 | I32: =SUM(E32,G32,H32) -> 4 | J32: 6
A33: 1998 | B33: George Pataki (R) | C33: No data | D33: No data | E33: 0 | F33: No data | G33: 0 | I33: =SUM(E33,G33,H33) -> 0
A34: 1997 | B34: George Pataki (R) | C34: No data | D34: No data | E34: 3 | F34: No data | G34: 0 | I34: =SUM(E34,G34,H34) -> 3 | J34: 5
A35: 1996 | B35: George Pataki (R) | C35: No data | D35: No data | E35: 0 | F35: No data | G35: 7 | I35: =SUM(E35,G35,H35) -> 7
A36: 1995 | B36: George Pataki (R) | C36: No data | D36: No data | E36: 0 | F36: No data | G36: 2 | I36: =SUM(E36,G36,H36) -> 2
A37: 1994 | B37: Mario Cuomo (D) | C37: No data | D37: No data | E37: No data | F37: No data | G37: No data | I37: =SUM(E37,G37,H37) -> 0
A38: 1993 | B38: Mario Cuomo (D) | C38: No data | D38: No data | E38: No data | F38: No data | G38: No data | I38: =SUM(E38,G38,H38) -> 0
A39: 1992 | B39: Mario Cuomo (D) | C39: No data | D39: No data | E39: No data | F39: No data | G39: No data | I39: =SUM(E39,G39,H39) -> 0
A40: 1991 | B40: Mario Cuomo (D) | C40: No data | D40: No data | E40: No data | F40: No data | G40: No data | I40: =SUM(E40,G40,H40) -> 0
...

Sheet other data
A1: Year | B1: Applications | C1: Grants | D1: Notes | E1: source
A2: 2023 | B2: 1193 | C2: 36 | E2: https://gothamist.com/news/more-than-1500-incarcerated-new-yorkers-are-asking-gov-hochul-for-the-year-end-gift-of-freedom | G2: https://www.cityandstateny.com/politics/2023/12/ahead-christmas-hochul-grants-pardons-and-commutations-16-people/393006/
A3: 2022 | B3: =857+441 -> 1298 | C3: 13 | D3: 857 applications for commutations and 441 requests for pardons pending | E3: https://www.nytimes.com/2022/12/21/nyregion/kathy-hochul-pardon-clemency.html
A4: 2021 | B4: 642 | C4: 0 | D4: thru Aug 9 | E4: https://www.prisonpolicy.org/reports/commutations.html#states
A5: 2020 | B5: 2184 | C5: 12 | E5: https://www.prisonpolicy.org/reports/commutations.html#states
A6: 2019 | B6: 1026 | C6: 0 | E6: https://www.prisonpolicy.org/reports/commutations.html#states
A7: 2018 | B7: 928 | C7: 7 | E7: https://www.prisonpolicy.org/reports/commutations.html#states
A8: 2017 | B8: 949 | C8: 2 | E8: https://www.prisonpolicy.org/reports/commutations.html#states
A9: 2016 | B9: 4775 | C9: 7 | E9: https://www.prisonpolicy.org/reports/commutations.html#states
A10: 2015 | B10: 515 | C10: 3 | E10: https://www.prisonpolicy.org/reports/commutations.html#states
A11: 2014 | B11: 408 | C11: 0 | E11: https://www.prisonpolicy.org/reports/commutations.html#states
A12: 2013 | B12: 266 | C12: 0 | E12: https://www.prisonpolicy.org/reports/commutations.html#states
A13: 2012 | B13: 297 | C13: 0 | E13: https://www.prisonpolicy.org/reports/commutations.html#states
A14: 2011 | B14: 449 | C14: 0 | E14: https://www.prisonpolicy.org/reports/commutations.html#states
A15: 2010 | B15: 1209 | C15: 2 | E15: https://www.prisonpolicy.org/reports/commutations.html#states
A16: 2009 | B16: 190 | C16: 1 | E16: https://www.prisonpolicy.org/reports/commutations.html#states
... A20: 2005 | B20: 190 | C20: 1 | E20: https://www.prisonpolicy.org/reports/commutations.html#states
B22: notes from rebecca:
B23: this data is clearly labeled as "applications for commutation" here https://www.prisonpolicy.org/reports/commutations.html#nyappendix
B24: that said the 2010 number looks more like what we had for commutations and pardon applications. (but not exactly! ours add to 1269 and this is 1209)
A26: clemency stats for all states (sort of)
A27: https://ccresourcecenter.org/state-restoration-profiles/50-state-comparisoncharacteristics-of-pardon-authorities-2/

Sheet Commutations
A1: Total Commutations: | D1: =Summary!E5 -> 74
A2: Date | B2: Governor | C2: First Name | D2: Last Name | E2: Bio
A3: 45282 | B3: Kathy Hochul | C3: Eric | D3: Davidson | E3: 54, was convicted of Burglary in the Second Degree and Criminal Possession of Stolen Property in the Fifth Degree in 2012. He was sentenced to 16 years to life in prison, of which he has served close to 14 years.
C4: Alexander | D4: Dockery | E4: 54, was convicted of Burglary in the Second Degree, Burglary in the Third Degree, Attempted Burglary in the Second Degree, and Criminal Trespass in the Second Degree between 2000 and 2002.
A5: 45146 | B5: Kathy Hochul | C5: Gregory | D5: Goodwine | E5: 56, was convicted of Robbery in the First Degree, Criminal Possession of a Weapon in the Third Degree, and Grand Larceny in the Fourth Degree in 2005 in relation to a purse snatching outside of a grocery store that did not result in physical injury.
C6: David | D6: Herion | E6: 49, was convicted of Attempted Murder in the Second Degree, Assault in the First Degree, Assault in the Second Degree, and Criminal Possession of a Weapon in the Second Degree in 1997.
C7: Myeshia | D7: Hawkins-Taylor | E7: 49, was convicted of Attempted Murder in the Second Degree in 2017. She was sentenced to 16 years in prison, and has served more than seven and a half years of her sentence.
A8: 45023 | B8: Kathy Hochul | C8: Bryon | D8: Russ | E8: 47, was convicted of four counts of Robbery in the First Degree, two counts of Burglary in the First Degree, Burglary in the Second Degree, Robbery in the Third Degree, Assault in the First Degree, Criminal Possession of a Weapon in the Second Degree, and Conspiracy in the Fourth Degree in 2001. Mr. Russ was sentenced to 40 years in prison, of which he has served close to 23 years. While incarcerated, Mr. Russ has enrolled in and continues to take courses toward his Bachelor's Degree, has worked as a teacher's assistant for other incarcerated individuals seeking their GED, has become an accomplished legal researcher, and earned a paralegal certification after completing an eight-month course in 2022. Mr. Russ has also engaged in a wide range of counseling and volunteer work, including as a facilitator of anti-violence and aggression replacement programs and a participant in Rehabilitation Through the Arts. With his wife, Mr. Russ also started an initiative that raises donations to buy backpacks and school supplies for children in need; now an annual event, this effort has led to more than 200 hundred backpacks and supplies being given out to children in New York State. Upon release, Mr. Russ will live with his wife.
C9: Joaquin | D9: Winfield | E9: 58, was convicted of Criminal Possession of A Controlled Substance in the First Degree, two counts of Criminal Possession of A Controlled Substance in the Third Degree, Criminal Sale of A Controlled Substance in the Third Degree, Criminal Use of Drug Paraphernalia in the Second Degree, and Criminal Possession of a Weapon in the Fourth Degree in 1997. Mr. Winfield was sentenced to 37 and a half years to life in prison under the Rockefeller Drug Laws in place at the time and has served more than 26 years. His sentence is now among the longest of any in the State stemming from a conviction for drug-related non-violent offenses. Under his original sentence, Mr. Winfield would not see the Board of Parole until 2034. His sentence is being commuted to allow him an earlier opportunity to appear before the Parole Board so that the board can make a determination about whether he is suitable for parole.
A10: 44916 | B10: Kathy Hochul | C10: Jacqueline | D10: Smalls | E10: 60, was convicted of Manslaughter in the First Degree, two counts of Criminal Sale of a Controlled Substance in the Third Degree, and two counts of Criminal Possession of a Controlled Substance in the Third Degree in 2013. Ms. Smalls is a survivor of domestic violence, having experienced several relationships in which she was subjected to physical, emotional, and financial abuse. Her present conviction stems from an incident in which her abuser entered her home in violation of two active orders of protection. This followed similar incidents in the months prior that resulted in Ms. Smalls' abuser choking and assaulting her, and thus fearing for her life, Ms. Smalls stabbed him once in the chest. She was sentenced to 15 years in prison and has served more than 10 years. While incarcerated, she has worked toward her GED and completed domestic violence programs. Upon release, Ms. Smalls will be reunited with her daughter.
C11: Anthony | D11: Evans | E11: 56, was convicted of Burglary in the Second Degree in 2004. He has served nearly 19 years of a 22-year to life sentence. At a young age, Mr. Evans was exposed to crime and substance abuse, and his family was greatly impacted by steel mill closures and deindustrialization in the Buffalo area. During nearly two decades of incarceration, he has earned his GED, become active in his religious community, rebuilt ties with family, and helped counsel other incarcerated individuals working to earn and maintain their sobriety. He has not had a disciplinary infraction in more than 15 years. Upon release, Mr. Evans will live with his wife and has a job offer at a commercial real estate business.
C12: Bruce | D12: Bryant | E12: 53, was convicted of Murder in the Second Degree, Attempted Murder in the Second Degree, and Criminal Possession of a Weapon in the Third Degree in 1996. He was 23 years old at the time of the crime and has served more than 30 years out of a 37.5-year to life sentence. During his three decades of incarceration, Mr. Bryant has earned an Associate's Degree and Bachelor's Degree, and recently earned a certification through an entrepreneurial training program. Mr. Bryant also facilitates anti-violence workshops and co-founded the Civic Duty Initiative, a program that has raised money for gun buy-backs, donated books to local communities, and raised money to provide children with backpacks and other charitable causes. He has also worked with a nonprofit organization to establish a mentoring program aimed at preventing youth violence and has also completed and facilitated numerous workshops aimed at self-development, including a focus on programs assisting children of incarcerated parents. Under his original sentence, Mr. Bryant would not see the Board of Parole until 2029. His sentence is being commuted to allow him an earlier opportunity to appear before the Parole Board so that the board can make a determination about whether he is suitable for parole.
C13: Stanley | D13: Bellamy | E13: 60, was convicted of Murder in the Second Degree, Attempted Murder in the Second Degree, and Robbery in the First Degree in 1987. He was 23 years old at the time of the crime and has served more than 37 years out of a 62-and-a-half-year to life sentence. During his nearly four decades of incarceration, Mr. Bellamy has earned his GED, Associate's Degree, and Bachelor's Degree, and has worked for years as a teaching assistant for Adult Basic Education and Pre-College courses for other incarcerated individuals. He also led a computer literacy program for incarcerated individuals, and helped launch a mentoring program aimed at teaching others about entrepreneurship. He served for years as the lead organizer of an annual anti-violence seminar at Sullivan Correctional Facility, and was a co-founder of the Civic Duty Initiative, a program that has raised money for gun buy-backs, donated books to local communities, and raised money to provide children with backpacks and other charitable causes. While incarcerated, Mr. Bellamy has earned recognition as a leader and mentor, and has developed and facilitated a wide range of programming on topics like conflict resolution, anger management, self-development, and personal responsibility. He has earned over 70 certificates, awards, and other forms of recognition for his accomplishments and contributions to others during his period of incarceration. Under his original sentence, Mr. Bellamy would not see the Board of Parole until 2048, when he would be 85 years old. His sentence is being commuted to allow him an earlier opportunity to appear before the Parole Board so that the board can make a determination about whether he is suitable for parole.
A14: 44554 | B14: Kathy Hochul | C14: Roger | D14: Cole | E14: 55, was originally sentenced to one hundred and twenty-five years to life in prison, having been put on trial during the Rockefeller Drug Law era during which extremely lengthy prison sentences were handed down for drug-related convictions. In 1989 and 1992, he was convicted of five counts of Criminal Sale of a Controlled Substance in the First Degree and one count each of Criminal Sale of a Firearm in the Second Degree and Criminal Possession of a Weapon in the Third Degree. His sentence was subsequently reduced on appeal to eighty-five to one hundred years, of which Mr. Cole has now served more than thirty years. If he were sentenced today, he likely would not have faced such a lengthy sentence. While incarcerated, Mr. Cole has earned his GED and an Associate Degree, and has completed numerous vocational training and certification programs, including legal research and law library management. He also earned a certificate for completing a three-year business course while incarcerated. Upon his release, Mr. Cole will be reunited with his mother and other family members in his home country of Jamaica who will provide housing and help him find employment.
A15: 2021 | B15: Andrew Cuomo | C15: Ulysses | D15: Boyd | E15: 66, was convicted of one count of second-degree Murder and two counts of second-degree Criminal Possession of a Weapon for an incident in which he was not the gunman.
C16: Richard "Lee" | D16: Chalk | E16: was convicted of two counts of second-degree Murder, two counts of first-degree Robbery, two counts of first-degree Burglary, and second-degree Criminal Possession of a Weapon in 1988, related to an incident in which he was the driver, not the gunman.
C17: Paul | D17: Clark
C18: Robert | D18: Ehrenberg | E18: 62, was convicted of two counts of second-degree Murder, and one count of first-degree Robbery and first-degree Burglary.
C19: David | D19: Gilbert | E19: 76, was convicted of three counts of second-degree Murder and four counts of first-degree Robbery in 1983.
C20: Nehru | D20: Gumbs | E20: 36, was convicted of first-degree Manslaughter, and second-degree Criminal Possession of a Weapon and Assault in 2005, crimes he committed at 18 years old.
C21: Greg | D21: Mingo | E21: 68, was convicted of four counts of second-degree Murder, first-degree Robbery, first-degree Burglary, and second-degree Criminal Possession of a Weapon
C22: Dantie | D22: Mitchell | E22: 41, was convicted of first-degree Robbery, Criminal Use of a Firearm, and Attempt to Knowingly Make/Possess Dangerous Contraband in Prison, two counts of first-degree Attempted Robbery, two counts of second-degree Criminal Possession of a Weapon, and fourth-degree Grand Larceny in 1997 and 2003, including crimes he committed at 17 years old and while homeless.
C23: Jon-Adrian | D23: Velasquez | E23: 45, was convicted of second-degree Murder and Attempted Murder, three counts of first-degree Robbery, and first-degree Attempted Robbery, in 199
A24: 44189 | B24: Andrew Cuomo | C24: Gus | D24: Bethea | E24: 38, was convicted of Robbery in the First Degree in 2003. Mr. Bethea has served 18 years of a 25-year sentence for two street robberies.
C25: Jacinto | D25: Cedeno | E25: 55, was convicted of Criminal Sale of a Controlled Substance in the First Degree, Criminal Possession of a Controlled Substance in the First Degree, Criminal Possession of a Controlled Substance in the Second Degree, and Criminal Possession of a Controlled Substance in the Third Degree in 1996.
C26: Theresa | D26: Debo | E26: 64, was convicted of Murder in the Second Degree in 2006. She has served 16 years of a 22 years to life sentence.
C27: Joseph | D27: Norman | E27: 60, was convicted of Robbery in the First Degree and Assault in the Second Degree in 2004.
C28: Maria | D28: Ordonez | E28: 26, was convicted of Manslaughter in the First Degree in 2018. She has served six years out of a nine-year sentence.
C29: Arnold | D29: Raimondo | E29: 70, was convicted of Murder in the Second Degree and Criminal Possession of a Weapon in the Second Degree in 1983.
C30: Clifton | D30: Williams | E30: 43, was convicted of Murder in the Second Degree, Attempted Robbery in the Second Degree, Criminal Possession of a Controlled Substance in the Third Degree, and Criminal Possession of a Controlled Substance in the Fourth Degree in 1996 and 1997, crimes he committed at 18-years-old.
A31: 2019 | B31: Andrew Cuomo | C31: No data
A32: 2018 | B32: Andrew Cuomo | C32: No data
A33: 43096 | B33: Andrew Cuomo | C33: Dominic | D33: Dupont | E33: 39, has served more than 20 years of a 25- to life sentence for Murder in the Second Degree and Criminal Possession of a Weapon in the Second Degree.
C34: Michael | D34: Flournoy | E34: 42, has served 21 years of a 25 to 50-year sentence for Attempted Murder in the 2nd Degree and other charges.
A35: 42734 | B35: Andrew Cuomo | C35: Judith | D35: Clark | E35: 67, has served over 35 years of her 75 years to life sentence. On October 14, 1983, she was convicted of Murder in the Second Degree and Robbery in the First Degree in Rockland County for driving the getaway vehicle in a 1981 Brinks armored car robbery.
C36: Anthony | D36: Desmae | E36: 34, has served almost eight years of his sentence of 10 years in prison following his conviction of Robbery in the Second Degree.
C37: Matthew | D37: Hattley | E37: 49, has served over 24 years of his sentence of 25 years to life for Murder in the Second Degree.
C38: Charlie | D38: Lee | E38: 73, has served more than 13 years of a 16-year sentence and has no prior criminal history.
C39: Felipe | D39: Rodriguez | E39: 51, has served almost 27 years of a 25 to life sentence following his conviction of Murder in the Second Degree and Criminal Possession of a Weapon in the Fourth Degree.
C40: Valerie | D40: Seeley | E40: 61, has served 15 years of a 19 to life sentence for Murder in the Second Degree after killing her live-in boyfriend.
...

Sheet Pardons
A1: Total Pardons : | D1: =Summary!G5 -> 257
A2: Date | B2: Governor | C2: First Name | D2: Last Name | E2: Bio
A3: 45282 | B3: Kathy Hochul | C3: Devon | D3: Cottman | E3: 49, has lived a crime-free life for 23 years. He is a United States citizen, serves as the primary caretaker to his children, and operates a small business. He was convicted of Criminal Possession of a Controlled Substance in the Third Degree in 2000.
C4: Holdemar | D4: Cruz | E4: 41, has lived a crime-free life for 18 years. He is a United States citizen.
C5: Vitality | D5: Dorum | E5: 41, has lived a crime-free life for 19 years. He came to the United States as a teenager and has lived here for approximately 24 years.
C6: Bernardo | D6: Encarnacion | E6: 70, has lived a crime-free life for 20 years. He has lived in the United States for approximately 25 years and has two children who are United States citizens.
C7: Miledys | D7: Jett | E7: 54, has lived a crime-free life for 31 years. She came to the United States as a teenager and has lived here for more than 40 years.
C8: Kayode | D8: Oseni | E8: 33, has lived a crime-free life for 13 years. He came to the United States when he was six years old and has now lived here for most of his life.
C9: Noel | D9: Watson | E9: 60, has lived a crime-free life for 30 years. He came to the United States in his twenties and has lived here for more than 30 years.
C10: Donnell | D10: Reed | E10: 55, has lived a crime-free life for 32 years. He is a United States citizen and military veteran, having first enlisted in the United States Army at age 19.
C11: Jose Antonio | D11: Reyes | E11: 48, has lived a crime-free life for 25 years. He is a United States citizen.
C12: Justin | D12: Riley | E12: 31, has lived a crime-free life for 14 years. He is a United States citizen.
C13: Andres | D13: Rivera | E13: 43, has lived a crime-free life for 22 years. He came to the United States as a teenager, has lived here for more than 30 years, and has child who is a United States citizen.
C14: Warren | D14: Stewart | E14: 42, has lived a crime-free life for 13 years. He came to the United States when he was a teenager, has lived here for approximately 28 years, and has immediate family members who are United States citizens.
A15: 45146 | B15: Kathy Hochul | C15: Nana | D15: Ampaw | E15: 56, has lived a crime free life for 15 years. She has lived in the United States for approximately 20 years, is married to a United States citizen, and has four children who are all United States citizens or lawful permanent residents. Ms. Ampaw has worked as a home health aide and an assistant for a mental health program while pursuing a degree in social work. Ms. Ampaw was convicted of Falsifying Business Records in the First Degree in 2007. A pardon will help her pursue naturalization to become a United States citizen.
C16: Christopher | D16: Dyer | E16: 38, has lived a crime free life for 17 years. He came to the United States when he was seven years old and lived here for approximately 25 years before being deported in 2017 due to his convictions. He is married to a United States citizen and has two United States children, both of whom are minors. Mr. Dyer had been living a crime free life for approximately 10 years when he applied for United States citizenship; the process instead resulted in his deportation, and his family has been separated ever since. Mr. Dyer was convicted of Attempted Robbery in the Second Degree in 2006 and Assault in the Third Degree in 2005. A pardon will help him return to the United States to be reunited with his family and community.
C17: Raul | D17: Labit | E17: 64, has lived a crime free life for 32 years. He first came to the United States in the 1980s and has lived here consistently for more than 20 years. He has a child and two grandchildren who are United States citizens, and he operates a contracting business doing renovations and remodeling. He was convicted of Criminal Possession of a Controlled Substance in the Seventh Degree in 1990. A pardon will help him pursue naturalization to become a United States citizen.
C18: Michael | D18: Martin | E18: 56, has lived a crime free life for 14 years. He has lived in the United States for more than 33 years and has numerous family members, including his father, two children, and one stepchild, who are United States citizens. Mr. Martin was convicted of Bail Jumping in the Second Degree in 1999 after missing court dates related to charges of which he was later acquitted. A pardon will help him avert the threat of deportation and pursue naturalization to become a United States citizen.
C19: David | D19: Garcia Nunez | E19: 60, has lived a crime free life for 30 years. He has lived in the United States for more than 40 years, is married to a United States citizen, and has five children who are United States citizens. He was convicted of Attempted Criminal Sale of a Controlled Substance in the Third Degree in 1987 and Attempted Criminal Possession of a Controlled Substance in the Third Degree in 1992. A pardon will help him pursue naturalization to become a United States citizen.
C20: Andrew | D20: Oxendine | E20: 63, has lived a crime free life for 41 years. He is a United States citizen and military veteran, having enlisted in the United States Marine Corps at age 17. He served on active duty and as a member of the reserves for several years before being honorably discharged in 1999. Mr. Oxendine also worked for a local housing opportunities commission for approximately three decades before recently retiring. Mr. Oxendine was convicted of Attempted Robbery in the Third Degree in 1982.
C21: Ramon | D21: Perez | E21: 58, has lived a crime free life for 31 years. He came to the United States as a teenager and has lived here for more than 30 years. He is married to a United States citizen and has five children and three stepchildren who are all United States citizens. He is an active member of his local community and operates a small business with his wife. He was convicted of Attempted Criminal Sale of a Controlled Substance in the Third Degree and Attempted Criminal Possession of a Controlled Substance in the Fourth Degree in 1991. A pardon will help him pursue naturalization to become a United States citizen.
C22: Edelberto | D22: Rendon | E22: 59, has lived a crime free life for 34 years. He has lived in the United States for more than 37 years and has two children who are both United States citizens. He has been employed in the food service industry for more than 30 years and is active in his local community. Mr. Rendon was convicted of Criminal Possession of a Controlled Substance in the Fourth Degree and Criminal Possession of a Controlled Substance in the Seventh Degree in 1989. A pardon will help avert the threat of deportation so that he can remain in the United States with his family and community.
C23: Sean | D23: Stephen | E23: 59, has lived a crime free life for 20 years. He came to the United States when he was approximately five years old and has lived here for more than 50 years. He has a child who is a United States citizen and serves as a source of support to several family members. He is an active member of his local community, including through involvement in youth mentorship programs, and he operates a small business. Mr. Stephen was convicted of Criminal Possession of a Controlled Substance in the Third Degree in 2003. A pardon will help avert the threat of deportation so that he can remain in the United States with his family and community.
C24: Henry | D24: Williams | E24: 70, has lived a crime free life for 27 years. He has lived in the United States for more than 25 years and is married to a United States citizen; together they have six children and numerous grandchildren who are also United States citizens. Mr. Williams was convicted of Criminal Sale of Marijuana in the Fourth Degree and Disorderly Conduct in 1996. A pardon will help him pursue naturalization to become a United States citizen.
A25: 45023 | B25: Kathy Hochul | C25: Asdrubal | D25: Gonzalez | E25: 64, has lived a crime free life for 30 years. Mr. Gonzalez entered the United States as a Lawful Permanent Resident in 1971 at the age of 13, more than 50 years ago. He has a wife and two daughters who are all U.S. citizens, has been gainfully employed at an engineering firm for close to three decades, and is an active member of his local church community. He was convicted of Attempted Criminal Sale of a Controlled Substance in the Third Degree in 1993 and Attempted Criminal Possession of a Controlled Substance in the Third Degree in 1991. A pardon will help him pursue naturalization to become a United States citizen.
C26: Ashan | D26: Grant | E26: 46, has lived a crime free life for 19 years. Mr. Grant, a Canadian citizen and resident, serves as a mentor in his community and operates a small business. He was convicted of Criminal Possession of Marijuana in the Fourth Degree in 2003. A pardon will help Mr. Grant visit his son and other family members living in the United States.
C27: Gerson | D27: Ramirez | E27: 36, has lived a crime free life for 13 years. Since his most recent conviction, he has earned a college degree and maintained employment at a restaurant for more than 10 years, now serving as the manager. Mr. Ramirez was brought to the United States when he was approximately 18 months old and has lived in the U.S. for nearly his entire life. Mr. Ramirez was convicted of Aggravated Unlicensed Operation of a Motor Vehicle and Aggravated DWI in 2009, and Driving Without Seatbelt, Following Too Close, Driving While Ability Impaired by Alcohol, and Driving Without License in 2004. A pardon will help Mr. Ramirez avert the threat of deportation and remain in the United States with his wife, infant child, and other U.S. citizen family members.
C28: Pawel | D28: Sztremer | E28: 46, has lived a crime free life for 23 years. Mr. Sztremer moved to the United States at 14 years old and has lived here for more than 30 years. He currently owns and operates a landscaping and snow removal business. Mr. Sztremer was convicted of Harassment in 1996, Petit Larceny in 1998, Criminal Mischief in the Fourth Degree in 1998, and Attempted Burglary in the Second Degree in 1999. A pardon will help remove the threat of deportation and help him pursue naturalization to become a United States citizen.
C29: Georgia | D29: Weir-Demercado | E29: 49, has lived a crime free life for 27 years and has earned an Associate's Degree, Bachelor's Degree, and a real estate license. She came to the United States at the age of six and has lived in the United States for more than 40 years. She is married to a United States citizen and has three United States citizen children. Ms. Weir-Demercado was convicted of Attempted Criminal Sale of a Controlled Substance in the Third Degree in 1995. A pardon will help her pursue naturalization to become a United States citizen.
A30: 44916 | B30: Kathy Hochul | C30: Paul | D30: Antoine | E30: 39, has lived a crime free life for 14 years. Mr. Antoine came to the United States when he was six years old and lived here for more than 20 years before being deported in 2010 due to his sole conviction for Attempted Criminal Sale of a Controlled Substance in the Third Degree in 2008. His mother is a U.S. citizen and continues to live in the United States. A pardon will help Mr. Antoine return to help care for his aging mother.
C31: Franklin | D31: Barcacel | E31: 54, has lived a crime free life for 23 years and is an active member of his local community, volunteering for translation and food distribution programs at local community centers and actively participating in his local church. Mr. Barcacel moved to the United States as a child, has lived here for more than 40 years, and has five children and a grandchild who are all U.S. citizens or Lawful Permanent Residents. Mr. Barcacel was convicted of Criminal Possession of Stolen Property in the Fourth Degree and Tampering With Witness in the Second Degree in 1999. A pardon will help him avoid deportation and remain in the United States with his family.
C32: Andres Pauline | D32: Castro | E32: 52, has lived a crime free life for 17 years. He is married to a U.S. citizen and has three U.S. citizen children. He and his wife operate two small businesses in the Bronx and are active members of their local church community. Mr. Paulino Castro was convicted of Attempted Criminal Possession of a Controlled Substance in the Third Degree in 2005. He has lived in the United States for more than 20 years, and a pardon would help him avoid deportation and remain here with his family.
C33: Denise Shelly-Ann | D33: Carter | E33: 46, has lived a crime free life for 23 years, works as a home health aide, and is an active member of her local church.
C34: Kurt | D34: Hawkins | E34: 54, has lived a crime free life for 31 years and worked for more than a decade at a local public works department. He has two children, two stepchildren, and a grandchild who are all U.S. citizens, including a daughter who serves in the U.S. Army. Mr. Hawkins was convicted of Criminal Possession of a Controlled Substance in the Fifth Degree and Petit Larceny in 1991. A pardon will help him pursue naturalization to become a United States citizen.
C35: Lesly | D35: Parfait | E35: 52, has lived a crime free life for 17 years and is employed as a concrete worker. He is active in his local union and has volunteered to teach construction skills to youth in his community. He is married to a U.S. citizen and has two children, four stepchildren, and seven grandchildren, all of whom are U.S. citizens. He is the primary earner and important source of support for his family. Mr. Parfait was convicted of Robbery in the Third Degree in 2005. He came to the United States at age 5 and has lived here for more than 45 years. A pardon will help him avoid deportation and remain in the United States with his family.
C36: Brenda Gordillo | D36: Plaza | E36: 57, has lived a crime free life for 17 years and is working to complete a hairdressing and cosmetology program, with a goal of establishing her own salon in the future. She has lived in the United States for more than 35 years. She was convicted of four counts of Criminal Possession of Stolen Property in the Fifth Degree and two counts of Petit Larceny between 1992 and 2005. A pardon will help Ms. Gordillo avoid deportation and remain in the United States.
C37: Amir | D37: Shaaban | E37: 45, has lived a crime free life for 14 years and operates a small business with his brother. He is married to a U.S. citizen and is a caretaker to his mother and mother-in-law, both of whom are also U.S. citizens. He moved to the United States as a child and has lived here for more than 30 years. Mr. Shaaban was convicted of Attempted Criminal Sale of a Controlled Substance in the Third Degree in 2008. A pardon will help Mr. Shaaban remain in the United States with his family.Denise Shelly-Ann Carter, 46, has lived a crime free life for 23 years, works as a home health aide, and is an active member of her local church. She has lived in the United States for more than 30 years. She was convicted of Attempted Criminal Sale of a Controlled Substance in the Third Degree, Criminal Possession of a Controlled Substance in the Seventh Degree, and Criminal Facilitation in the Fourth Degree in 1999. A pardon will help Ms. Carter remain in the United States, where she has lived most of her life.
C38: Paola Jovana Espinosa | D38: Yunda | E38: 47, has lived a crime free life for 19 years. She has lived in the United States for more than 25 years and is the mother of two U.S. citizen children, one of whom is six years old. She was convicted of two counts of Criminal Possession of Marijuana in the First Degree in 2003. A pardon will help Ms. Espinosa remain in the United States with her children and extended family.
A39: 44554 | B39: Kathy Hochul | C39: Edilberta Reyes | D39: Canales | E39: 56, has lived a crime free life for 12 years and has worked as a home health aide for several years, including throughout the COVID-19 pandemic. She is a survivor of domestic abuse. Ms. Reyes has lived in the United States since fleeing conflict in her home country in 1988. She is the primary caretaker and provider for her son, who is a U.S. citizen. Ms. Reyes was convicted of Criminal Contempt in the Second Degree, Resisting Arrest, Assault in the Third Degree, Endangering the Welfare of a Child, Falsely Reporting an Incident to Law Enforcement in the Third Degree, and Petit Larceny between 2007 and 2009, and Attempted Petit Larceny in 1993. Her convictions between 2007 and 2009 occurred during a period in her life when she was actively trying to escape an abusive relationship. A pardon will help Ms. Reyes avoid deportation, for which she is facing an upcoming hearing, and remain in the United States with her son.
C40: Hanley | D40: Gomez | E40: 41, has been crime free for seven years. Mr. Gomez has lived in the United States since he was eight years old, and currently works for a New York City-based meal delivery company. He also volunteers at a local food pantry. Mr. Gomez is also the primary caretaker and provider for his 10-year-old child. He was convicted of Criminal Possession of a Controlled Substance in the Seventh Degree, Resisting Arrest, DWAI, and Attempted Criminal Mischief between 1998 and 2011. A pardon will help ensure Mr. Gomez can remain in the United States with his son and extended family.
...

Sheet Sources
A1: https://www.nytimes.com/1975/12/25/archives/clemency-given-to-sostre-and-7-sakharov-and-others-urged-governor.html
A2: https://www.nytimes.com/1975/12/26/archives/governors-clemency.html?searchResultPosition=38
A3: https://www.nytimes.com/1981/11/26/nyregion/carey-gives-clemency-to-11-jailed-on-drugs.html
A4: https://www.upi.com/Archives/1982/05/13/A-convict-who-was-granted-clemency-by-Gov-Hugh/4887390110400/
A5: https://www.nytimes.com/1997/12/25/nyregion/governor-commutes-sentences-of-3-convicted-on-drug-charges.html
A6: https://www.nytimes.com/1999/12/24/nyregion/4-first-time-drug-offenders-granted-clemency-by-pataki.html
A7: https://www.nytimes.com/2002/12/25/nyregion/pataki-grants-clemency-to-4-in-prison.html
A8: https://www.nytimes.com/2005/12/25/nyregion/drug-convict-wins-grant-of-clemency-from-pataki.html
A9: https://www.nytimes.com/2007/12/22/nyregion/22pardon.html
A10: https://observer.com/2008/12/paterson-grants-two-clemencies/
A11: https://www.theroot.com/freed-from-prison-but-still-in-pain-1790882144
A12: https://abcnews.go.com/US/ny-gov-david-paterson-commutes-john-whites-sentence/story?id=12471371
... A20: https://wayback.archive-it.org/8438/20211005043024/https://gov56.ny.gov/news/governor-cuomo-grants-clemency-four-individuals-and-launches-pro-bono-clemency-program

Sheet for video
A1: New York States grants less clemencies per incarcerated person than any other state its size | H1: older history of prison populations
B2: I have no idea where to start with this right now | H2: https://bjs.ojp.gov/library/publications/historical-statistics-prisoners-state-and-federal-institutions-yearend-1925-86
B3: I wonder if we make a map of the US and fill in some numbers? this feels like it would end up too text-dense and hard to read
A6: Rate of Clemencies granted (in New York) has gone down by _____ % (over ____ years)
B7: Can I suggest instead that we graph the number of clemencies vs the number of people in prison?
A12: Graph showing other Clemency Rates Compared to New York
A18: In the 1980s and 90s, New York State's courts sentenced people to longer sentences than in any other time in history. Many of those sentenced are still incarcerated.
B19: This is not quite the right way to show this but feels closer (it took 3 tabs in another spreadsheet to make this, happy to share)
A23: Graph Showing Incarceration Rates by Race.
B24: https://www.prisonpolicy.org/graphs/rates2021/NY_Rates_2021.html
B25: i can see if the sources are updated and try to make this for 2023 but basically we want this graph maybe?
B26: https://www.prisonpolicy.org/graphs/disparities2021/NY_racial_disparities_2021.html
B28: alternately this
B29: https://trends.vera.org/state/NY
A33: this was almost useful but the most severe thing they break out is "sentenced to prison"
A34: https://app.powerbigov.us/view?r=eyJrIjoiMGQwYWFjMmYtNTE0Ni00YmZhLTg4MmYtMzczYjVkMzYxNjM5IiwidCI6IjM0NTZmZTkyLWNiZDEtNDA2ZC1iNWEzLTUzNjRiZWMwYTgzMyJ9
A37: prison population in NY state source https://csat.bjs.ojp.gov/advanced-query
A38: State | B38: 1978 | C38: 1979 | D38: 1980 | E38: 1981 | F38: 1982 | G38: 1983 | H38: 1984 | I38: 1985 | J38: 1986 | K38: 1987 | L38: 1988 | M38: 1989 | N38: 1990 | O38: 1991 | P38: 1992 | Q38: 1993 | R38: 1994 | S38: 1995 | T38: 1996 | U38: 1997 | V38: 1998 | W38: 1999 | X38: 2000 | Y38: 2001 | Z38: 2002 | AA38: 2003 | AB38: 2004 | AC38: 2005 | AD38: 2006 | AE38: 2007 | AF38: 2008 | AG38: 2009 | AH38: 2010 | AI38: 2011 | AJ38: 2012 | AK38: 2013 | AL38: 2014 | AM38: 2015 | AN38: 2016 | AO38: 2017 | AP38: 2018 | AQ38: 2019
A39: NEW YORK | B39: 20459 | C39: 20856 | D39: 21815 | E39: 25494 | F39: 27945 | G39: 30510 | H39: 33109 | I39: 34507 | J39: 38449 | K39: 40842 | L39: 44560 | M39: 51232 | N39: 54895 | O39: 57862 | P39: 61736 | Q39: 64569 | R39: 66750 | S39: 68486 | T39: 69709 | U39: 69108 | V39: 72289 | W39: 72899 | X39: 70199 | Y39: 67533 | Z39: 67065 | AA39: 65198 | AB39: 63751 | AC39: 62743 | AD39: 63315 | AE39: 62620 | AF39: 60347 | AG39: 58687 | AH39: 56656 | AI39: 55436 | AJ39: 54210 | AK39: 53550 | AL39: 52518 | AM39: 51727 | AN39: 50716 | AO39: 49461 | AP39: 46636 | AQ39: 43500
A42: 2019 inmates, by year admitted
A43: State | B43: 1963 | C43: 1966 | D43: 1970 | E43: 1971 | F43: 1972 | G43: 1973 | H43: 1974 | I43: 1975 | J43: 1976 | K43: 1977 | L43: 1978 | M43: 1979 | N43: 1980 | O43: 1981 | P43: 1982 | Q43: 1983 | R43: 1984 | S43: 1985 | T43: 1986 | U43: 1987 | V43: 1988 | W43: 1989 | X43: 1990 | Y43: 1991 | Z43: 1992 | AA43: 1993 | AB43: 1994 | AC43: 1995 | AD43: 1996 | AE43: 1997 | AF43: 1998 | AG43: 1999 | AH43: 2000 | AI43: 2001 | AJ43: 2002 | AK43: 2003 | AL43: 2004 | AM43: 2005 | AN43: 2006 | AO43: 2007 | AP43: 2008 | AQ43: 2009 | AR43: 2010 | AS43: 2011 | AT43: 2012 | AU43: 2013 | AV43: 2014 | AW43: 2015 | AX43: 2016 | AY43: 2017 | AZ43: 2018 | BA43: 2019
A44: NEW YORK | B44: * | C44: * | D44: * | E44: * | F44: * | G44: * | H44: * | I44: * | J44: * | K44: 11 | L44: 14 | M44: * | N44: 25 | O44: 48 | P44: 33 | Q44: 46 | R44: 45 | S44: 58 | T44: 63 | U44: 53 | V44: 68 | W44: 75 | X44: 81 | Y44: 115 | Z44: 115 | AA44: 166 | AB44: 182 | AC44: 248 | AD44: 272 | AE44: 302 | AF44: 273 | AG44: 288 | AH44: 334 | AI44: 342 | AJ44: 398 | AK44: 429 | AL44: 473 | AM44: 483 | AN44: 506 | AO44: 580 | AP44: 620 | AQ44: 666 | AR44: 857 | AS44: 885 | AT44: 1124 | AU44: 1331 | AV44: 1690 | AW44: 2199 | AX44: 3263 | AY44: 4887 | AZ44: 7240 | BA44: 12568
A54: update - the data is pretty incomplete esp with folks incarcerated before about 2000
A55: from here ("offender characteristics" and filter by age of release, and NY state, can do all years back to 1999)
A56: https://csat.bjs.ojp.gov/advanced-query
B57: 18-24 years | C57: 25-34 years | D57: 35-44 years | E57: 45-54 years | F57: 55+ years
A58: 2019, age at release | B58: 1965 | C58: 7836 | D58: 5456 | E58: 3456 | F58: 2190
A59: 2019 releases, age at admission | B59: 3681 | C59: 7930 | D59: 4938 | E59: 2973 | F59: 1383
A66: historical data here, slightly digitized
A67: https://www.ojp.gov/pdffiles1/Digitization/111098NCJRS.pdf
C68: 1925
A69: New | B69: York | C69: 12067 | D69: 15409 | E69: 15353 | F69: 15883 | G69: 14397 | H69: 13399 | I69: 13221
B71: 1925 | C71: 6820
B72: =B71+1 -> 1926 | C72: 7367
B73: =B72+1 -> 1927 | C73: 7583
B74: =B73+1 -> 1928 | C74: 7819
B75: =B74+1 -> 1929 | C75: 8135
B76: =B75+1 -> 1930 | C76: 8856
B77: =B76+1 -> 1931 | C77: 9089
B78: =B77+1 -> 1932 | C78: 9613
...
